<?xml version="1.0" encoding="UTF-8"?>
<robot name="lbr_iisy11_r1300_robotiq_140">
  <joint name="world-base_link" type="fixed">
    <parent link="lbr_iisy11_r1300"/>
    <child link="base_link"/>
    <origin rpy="0 0 0" xyz="0 0 0"/>
  </joint>
  <joint name="joint_1" type="revolute">
    <axis xyz="0.0 0.0 1.0"/>
    <child link="link_1"/>
    <limit effort="4.0584E2" lower="-3.2288591125E0" upper="3.2288591125E0" velocity="3.49065850398866E0"/>
    <origin rpy="3.141592653589793 -0.0 0.0" xyz="0.0 0.0 0.1845"/>
    <parent link="base_link"/>
  </joint>
  <joint name="joint_2" type="revolute">
    <axis xyz="0.0 0.0 1.0"/>
    <child link="link_2"/>
    <limit effort="366.247685" lower="-4.014257279586958E0" upper="8.726646259971648E-1" velocity="3.490656"/>
    <origin rpy="1.5707963267948966 0.0 -0.0" xyz="0.0 0.1011 -0.1155"/>
    <parent link="link_1"/>
  </joint>
  <joint name="joint_3" type="revolute">
    <axis xyz="0.0 0.0 1.0"/>
    <child link="link_3"/>
    <limit effort="1.47189439778934E2" lower="-2.617993875E0" upper="2.617993875E0" velocity="3.49065850398866E0"/>
    <origin rpy="0.0 -0.0 0.0" xyz="0.59 0.0 0.0237"/>
    <parent link="link_2"/>
  </joint>
  <joint name="joint_4" type="revolute">
    <axis xyz="0.0 0.0 1.0"/>
    <child link="link_4"/>
    <limit effort="6.54825468125571E1" lower="-3.14159265E0" upper="3.14159265E0" velocity="4.01425727958696E0"/>
    <origin rpy="1.5707963267948966 -0.0 -1.5707963267948966" xyz="0.1139 0.0 0.0774"/>
    <parent link="link_3"/>
  </joint>
  <joint name="joint_5" type="revolute">
    <axis xyz="0.0 0.0 1.0"/>
    <child link="link_5"/>
    <limit effort="6.46576468348751E1" lower="-1.919862175E0" upper="1.919862175E0" velocity="4.53785605518526E0"/>
    <origin rpy="0.0 1.5707963267948966 1.5707963267948966" xyz="0.0 0.0507 -0.4181"/>
    <parent link="link_4"/>
  </joint>
  <joint name="joint_6" type="revolute">
    <axis xyz="0.0 0.0 1.0"/>
    <child link="link_6"/>
    <limit effort="1.57202326869092E1" lower="-3.83972435E0" upper="3.83972435E0" velocity="7.50491578357562E0"/>
    <origin rpy="1.5707963267948966 -0.0 -1.5707963267948966" xyz="0.0837 0.0 -0.0507"/>
    <parent link="link_5"/>
  </joint>
  <joint name="ee_link_root_joint" type="fixed">
    <origin xyz="0.0 0.0 -0.0943" rpy="3.1415927 0. 3.1415927"/>
    <parent link="link_6"/>
    <child link="ee_link_robotiq_arg2f_base_link"/>
  </joint>
  <joint name="finger_joint" type="revolute">
    <origin xyz="-0. -0.030601 0.054905" rpy="-2.2957964 0. -3.1415927"/>
    <parent link="ee_link_robotiq_arg2f_base_link"/>
    <child link="left_outer_knuckle"/>
    <axis xyz="1. 0. 0."/>
    <limit lower="0." upper="0.7" effort="1000." velocity="1.9999999"/>
  </joint>
  <joint name="gripper_pos_joint" type="fixed">
    <origin xyz="0. 0. 0.175" rpy="0. 0. 0."/>
    <parent link="ee_link_robotiq_arg2f_base_link"/>
    <child link="gripper_center"/>
    <axis xyz="1. 0. 0."/>
    <limit lower="0." upper="0.7" effort="1000." velocity="1.9999999"/>
  </joint>
  <joint name="left_inner_finger_joint" type="revolute">
    <origin xyz="0. -0.0999754 -0.0022185" rpy="-0.725 0. 3.1415927"/>
    <parent link="left_outer_knuckle"/>
    <child link="left_inner_finger"/>
    <axis xyz="1. 0. 0."/>
    <limit lower="-0.14" upper="0.84" effort="0." velocity="17453.2925199"/>
  </joint>
  <joint name="left_inner_knuckle_joint" type="revolute">
    <origin xyz="-0. -0.0127 0.06142" rpy="2.2957964 0. 0. "/>
    <parent link="ee_link_robotiq_arg2f_base_link"/>
    <child link="left_inner_knuckle"/>
    <axis xyz="1. 0. 0."/>
    <limit lower="-0.84" upper="0.14" effort="0." velocity="17453.2925199"/>
  </joint>
  <joint name="right_inner_finger_joint" type="revolute">
    <origin xyz="0. 0.0999754 -0.0022185" rpy="-0.725 0. 0. "/>
    <parent link="right_outer_knuckle"/>
    <child link="right_inner_finger"/>
    <axis xyz="1. 0. 0."/>
    <limit lower="-0.14" upper="0.84" effort="0." velocity="17453.2925199"/>
  </joint>
  <joint name="right_inner_knuckle_joint" type="revolute">
    <origin xyz="-0. 0.0127 0.06142" rpy="2.2957964 0. 3.1415925"/>
    <parent link="ee_link_robotiq_arg2f_base_link"/>
    <child link="right_inner_knuckle"/>
    <axis xyz="1. 0. 0."/>
    <limit lower="-0.84" upper="0.14" effort="0." velocity="17453.2925199"/>
  </joint>
  <joint name="right_outer_knuckle_joint" type="revolute">
    <origin xyz="-0. 0.030601 0.054905" rpy="2.2957964 0. -3.1415925"/>
    <parent link="ee_link_robotiq_arg2f_base_link"/>
    <child link="right_outer_knuckle"/>
    <axis xyz="1. 0. 0."/>
    <limit lower="-0.84" upper="0.14" effort="0." velocity="17453.2925199"/>
  </joint>
  <link name="lbr_iisy11_r1300"/>
  <link name="base_link">
    <collision>
      <geometry>
        <mesh filename="../meshes/lbr_iisy11_r1300/collision/base_link.stl"/>
      </geometry>
      <origin rpy="-0.0 0.0 -0.0" xyz="0.0 0.0 0.0"/>
    </collision>
    <visual>
      <geometry>
        <mesh filename="../meshes/lbr_iisy11_r1300/visual/base_link.stl"/>
      </geometry>
      <origin rpy="-0.0 0.0 -0.0" xyz="0.0 0.0 0.0"/>
      <material name="">
        <color rgba="0.9450980392156862 0.9254901960784314 1.0 1.0"/>
      </material>
    </visual>
  </link>
  <link name="link_1">
    <collision>
      <geometry>
        <mesh filename="../meshes/lbr_iisy11_r1300/collision/link_1.stl"/>
      </geometry>
      <origin rpy="-0.0 0.0 -0.0" xyz="0.0 0.0 0.0"/>
    </collision>
    <inertial>
      <inertia ixx="0.0489108039022503" ixy="0.0" ixz="0.0" iyy="0.038370593540088" iyz="0.0" izz="0.0522121642769911"/>
      <mass value="9.62E0"/>
      <origin rpy="-1.3035636348359196 -0.7815781053554712 1.2529437882898178" xyz="0.00344301039501039 0.0191980353430353 -0.08662803846153849"/>
    </inertial>
    <visual>
      <geometry>
        <mesh filename="../meshes/lbr_iisy11_r1300/visual/link_1.stl"/>
      </geometry>
      <origin rpy="-0.0 0.0 -0.0" xyz="0.0 0.0 0.0"/>
      <material name="">
        <color rgba="0.9450980392156862 0.9254901960784314 1.0 1.0"/>
      </material>
    </visual>
  </link>
  <link name="link_2">
    <collision>
      <geometry>
        <mesh filename="../meshes/lbr_iisy11_r1300/collision/link_2.stl"/>
      </geometry>
      <origin rpy="-0.0 0.0 -0.0" xyz="0.0 0.0 0.0"/>
    </collision>
    <inertial>
      <inertia ixx="0.609923712050298" ixy="0.0" ixz="0.0" iyy="0.0385097671170806" iyz="0.0" izz="0.617803845441985"/>
      <mass value="9.86515786038357E0"/>
      <origin rpy="-0.0037282594736534596 -0.018939981545576166 -1.569953728930981" xyz="0.249085185084359 -0.00442629366790902 -0.0535128397562821"/>
    </inertial>
    <visual>
      <geometry>
        <mesh filename="../meshes/lbr_iisy11_r1300/visual/link_2.stl"/>
      </geometry>
      <origin rpy="-0.0 0.0 -0.0" xyz="0.0 0.0 0.0"/>
      <material name="">
        <color rgba="0.9450980392156862 0.9254901960784314 1.0 1.0"/>
      </material>
    </visual>
  </link>
  <link name="link_3">
    <collision>
      <geometry>
        <mesh filename="../meshes/lbr_iisy11_r1300/collision/link_3.stl"/>
      </geometry>
      <origin rpy="-0.0 0.0 -0.0" xyz="0.0 0.0 0.0"/>
    </collision>
    <inertial>
      <inertia ixx="0.0181557035426496" ixy="0.0" ixz="0.0" iyy="0.0346916391676837" iyz="0.0" izz="0.037776951242458"/>
      <mass value="7.49283573690527E0"/>
      <origin rpy="0.1692981167548117 0.5271433699021747 -2.9605806714357508" xyz="0.0438696763639649 -0.00482189531013714 0.044913251068375"/>
    </inertial>
    <visual>
      <geometry>
        <mesh filename="../meshes/lbr_iisy11_r1300/visual/link_3.stl"/>
      </geometry>
      <origin rpy="-0.0 0.0 -0.0" xyz="0.0 0.0 0.0"/>
      <material name="">
        <color rgba="0.9450980392156862 0.9254901960784314 1.0 1.0"/>
      </material>
    </visual>
  </link>
  <link name="link_4">
    <collision>
      <geometry>
        <mesh filename="../meshes/lbr_iisy11_r1300/collision/link_4.stl"/>
      </geometry>
      <origin rpy="-0.0 0.0 -0.0" xyz="0.0 0.0 0.0"/>
    </collision>
    <inertial>
      <inertia ixx="0.0283133115058557" ixy="0.0" ixz="0.0" iyy="0.15625788909506" iyz="0.0" izz="0.163792683235523"/>
      <mass value="7.09182257561761E0"/>
      <origin rpy="1.4927296069780172 -1.403978512066052 -1.5036439267584298" xyz="-7.163989476214221E-5 0.0445982847464326 -0.175445521620292"/>
    </inertial>
    <visual>
      <geometry>
        <mesh filename="../meshes/lbr_iisy11_r1300/visual/link_4.stl"/>
      </geometry>
      <origin rpy="-0.0 0.0 -0.0" xyz="0.0 0.0 0.0"/>
      <material name="">
        <color rgba="0.9450980392156862 0.9254901960784314 1.0 1.0"/>
      </material>
    </visual>
  </link>
  <link name="link_5">
    <collision>
      <geometry>
        <mesh filename="../meshes/lbr_iisy11_r1300/collision/link_5.stl"/>
      </geometry>
      <origin rpy="-0.0 0.0 -0.0" xyz="0.0 0.0 0.0"/>
    </collision>
    <inertial>
      <inertia ixx="0.00667288072123254" ixy="0.0" ixz="0.0" iyy="0.00503543168148481" iyz="0.0" izz="0.00841044585602456"/>
      <mass value="2.4516241997261E0"/>
      <origin rpy="0.4256203528755516 0.14544264795709014 1.2195648324165669" xyz="0.0384076101043046 0.00235993465013012 -0.0244545111288499"/>
    </inertial>
    <visual>
      <geometry>
        <mesh filename="../meshes/lbr_iisy11_r1300/visual/link_5.stl"/>
      </geometry>
      <origin rpy="-0.0 0.0 -0.0" xyz="0.0 0.0 0.0"/>
      <material name="">
        <color rgba="0.9450980392156862 0.9254901960784314 1.0 1.0"/>
      </material>
    </visual>
  </link>
  <link name="link_6">
    <collision>
      <geometry>
        <mesh filename="../meshes/lbr_iisy11_r1300/collision/link_6.stl"/>
      </geometry>
      <origin rpy="-0.0 0.0 -0.0" xyz="0.0 0.0 0.0"/>
    </collision>
    <inertial>
      <inertia ixx="0.00390274036654823" ixy="0.0" ixz="0.0" iyy="0.00286930887521153" iyz="0.0" izz="0.00403512413298348"/>
      <mass value="1.23566751268437E0"/>
      <origin rpy="-0.051936335875096745 -0.1296523529795729 -0.0038347791577379832" xyz="0.00315856028595676 0.0135678555121583 -0.038876254431844504"/>
    </inertial>
    <visual>
      <geometry>
        <mesh filename="../meshes/lbr_iisy11_r1300/visual/link_6.stl"/>
      </geometry>
      <origin rpy="-0.0 0.0 -0.0" xyz="0.0 0.0 0.0"/>
      <material name="">
        <color rgba="0.9450980392156862 0.9254901960784314 1.0 1.0"/>
      </material>
    </visual>
  </link>
  <link name="ee_link_robotiq_arg2f_base_link">
    <inertial>
      <origin rpy="0 0 0" xyz="8.625E-08 -4.6583E-06 0.03145"/>
      <mass value="0.22652"/>
      <inertia ixx="0.00020005" ixy="-4.2442E-10" ixz="-2.9069E-10" iyy="0.00017832" iyz="-3.4402E-08" izz="0.00013478"/>
    </inertial>
    <visual>
      <origin rpy="0 0 0" xyz="0 0 0"/>
      <geometry>
        <mesh filename="../robotiq_2f_140_gripper_visualization/meshes/visual/robotiq_arg2f_base_link.stl"/>
      </geometry>
      <material name="">
        <color rgba="0.1 0.1 0.1 1"/>
      </material>
    </visual>
    <collision>
      <origin rpy="0 0 0" xyz="0 0 0"/>
      <geometry>
        <mesh filename="../robotiq_2f_140_gripper_visualization/meshes/collision/robotiq_arg2f_base_link.stl"/>
      </geometry>
    </collision>
  </link>
  <link name="left_outer_knuckle">
    <inertial>
      <origin rpy="0 0 0" xyz="-0.000200000000003065 0.0199435877845359 0.0292245259211331"/>
      <mass value="0.00853198276973456"/>
      <inertia ixx="2.89328108496468E-06" ixy="-1.57935047237397E-19" ixz="-1.93980378593255E-19" iyy="1.86719750325683E-06" iyz="-1.21858577871576E-06" izz="1.21905238907251E-06"/>
    </inertial>
    <visual>
      <origin rpy="0 0 0" xyz="0 0 0"/>
      <geometry>
        <mesh filename="../robotiq_2f_140_gripper_visualization/meshes/visual/robotiq_arg2f_140_outer_knuckle.stl"/>
      </geometry>
      <material name="">
        <color rgba="0.792156862745098 0.819607843137255 0.933333333333333 1"/>
      </material>
    </visual>
    <collision>
      <origin rpy="0 0 0" xyz="0 0 0"/>
      <geometry>
        <mesh filename="../robotiq_2f_140_gripper_visualization/meshes/collision/robotiq_arg2f_140_outer_knuckle.stl"/>
      </geometry>
    </collision>
  </link>
  <link name="left_inner_finger">
    <inertial>
      <origin rpy="0 0 0" xyz="0.000299999999999317 0.0160078233491243 -0.0136945669206257"/>
      <mass value="0.0104003125914103"/>
      <inertia ixx="2.71909453810972E-06" ixy="1.35402465472579E-21" ixz="-7.1817349065269E-22" iyy="7.69100314106116E-07" iyz="6.74715432769696E-07" izz="2.30315190420171E-06"/>
    </inertial>
    <visual>
      <origin rpy="0 0 0" xyz="0 0 0"/>
      <geometry>
        <mesh filename="../robotiq_2f_140_gripper_visualization/meshes/visual/robotiq_arg2f_140_inner_finger.stl"/>
      </geometry>
      <material name="">
        <color rgba="0.1 0.1 0.1 1"/>
      </material>
    </visual>
    <collision>
      <origin rpy="0 0 0" xyz="0 0 0"/>
      <geometry>
        <mesh filename="../robotiq_2f_140_gripper_visualization/meshes/collision/robotiq_arg2f_140_inner_finger.stl"/>
      </geometry>
    </collision>
  </link>
  <link name="left_inner_knuckle">
    <inertial>
      <origin rpy="0 0 0" xyz="0.000123011831763771 0.0507850843201817 0.00103968640075166"/>
      <mass value="0.0271177346495152"/>
      <inertia ixx="2.61910379223783E-05" ixy="-2.43616858946494E-07" ixz="-6.37789906117123E-09" iyy="2.8270243746167E-06" iyz="-5.37200748039765E-07" izz="2.83695868220296E-05"/>
    </inertial>
    <visual>
      <origin rpy="0 0 0" xyz="0 0 0"/>
      <geometry>
        <mesh filename="../robotiq_2f_140_gripper_visualization/meshes/visual/robotiq_arg2f_140_inner_knuckle.stl"/>
      </geometry>
      <material name="">
        <color rgba="0.1 0.1 0.1 1"/>
      </material>
    </visual>
    <collision>
      <origin rpy="0 0 0" xyz="0 0 0"/>
      <geometry>
        <mesh filename="../robotiq_2f_140_gripper_visualization/meshes/collision/robotiq_arg2f_140_inner_knuckle.stl"/>
      </geometry>
    </collision>
  </link>
  <link name="right_outer_knuckle">
    <inertial>
      <origin rpy="0 0 0" xyz="-0.000200000000003065 0.0199435877845359 0.0292245259211331"/>
      <mass value="0.00853198276973456"/>
      <inertia ixx="2.89328108496468E-06" ixy="-1.57935047237397E-19" ixz="-1.93980378593255E-19" iyy="1.86719750325683E-06" iyz="-1.21858577871576E-06" izz="1.21905238907251E-06"/>
    </inertial>
    <visual>
      <origin rpy="0 0 0" xyz="0 0 0"/>
      <geometry>
        <mesh filename="../robotiq_2f_140_gripper_visualization/meshes/visual/robotiq_arg2f_140_outer_knuckle.stl"/>
      </geometry>
      <material name="">
        <color rgba="0.792156862745098 0.819607843137255 0.933333333333333 1"/>
      </material>
    </visual>
    <collision>
      <origin rpy="0 0 0" xyz="0 0 0"/>
      <geometry>
        <mesh filename="../robotiq_2f_140_gripper_visualization/meshes/collision/robotiq_arg2f_140_outer_knuckle.stl"/>
      </geometry>
    </collision>
  </link>
  <link name="right_inner_finger">
    <inertial>
      <origin rpy="0 0 0" xyz="0.000299999999999317 0.0160078233491243 -0.0136945669206257"/>
      <mass value="0.0104003125914103"/>
      <inertia ixx="2.71909453810972E-06" ixy="1.35402465472579E-21" ixz="-7.1817349065269E-22" iyy="7.69100314106116E-07" iyz="6.74715432769696E-07" izz="2.30315190420171E-06"/>
    </inertial>
    <visual>
      <origin rpy="0 0 0" xyz="0 0 0"/>
      <geometry>
        <mesh filename="../robotiq_2f_140_gripper_visualization/meshes/visual/robotiq_arg2f_140_inner_finger.stl"/>
      </geometry>
      <material name="">
        <color rgba="0.1 0.1 0.1 1"/>
      </material>
    </visual>
    <collision>
      <origin rpy="0 0 0" xyz="0 0 0"/>
      <geometry>
        <mesh filename="../robotiq_2f_140_gripper_visualization/meshes/collision/robotiq_arg2f_140_inner_finger.stl"/>
      </geometry>
    </collision>
  </link>
  <link name="right_inner_knuckle">
    <inertial>
      <origin rpy="0 0 0" xyz="0.000123011831763771 0.0507850843201817 0.00103968640075166"/>
      <mass value="0.0271177346495152"/>
      <inertia ixx="2.61910379223783E-05" ixy="-2.43616858946494E-07" ixz="-6.37789906117123E-09" iyy="2.8270243746167E-06" iyz="-5.37200748039765E-07" izz="2.83695868220296E-05"/>
    </inertial>
    <visual>
      <origin rpy="0 0 0" xyz="0 0 0"/>
      <geometry>
        <mesh filename="../robotiq_2f_140_gripper_visualization/meshes/visual/robotiq_arg2f_140_inner_knuckle.stl"/>
      </geometry>
      <material name="">
        <color rgba="0.1 0.1 0.1 1"/>
      </material>
    </visual>
    <collision>
      <origin rpy="0 0 0" xyz="0 0 0"/>
      <geometry>
        <mesh filename="../robotiq_2f_140_gripper_visualization/meshes/collision/robotiq_arg2f_140_inner_knuckle.stl"/>
      </geometry>
    </collision>
  </link>
  <link name="gripper_center"/>

</robot>
